Workbook

Sheet retail_sales_dataset (2)
A1: Transaction ID | B1: Date | C1: Year | D1: Customer ID | E1: Gender | F1: Age | G1: Generation | H1: Product Category | I1: Quantity | J1: Price per Unit | K1: Total sales | L1: 2023 Commission | M1: 2024 Commission | N1: Date Based Commission | P1: Rate %
A2: 1 | B2: 45254 | C2: =YEAR(B2) -> 2023 | D2: CUST001 | E2: Male | F2: 34 | G2: {=_xlfn.IFS(F2<30,"Young Adult",F2<50,"Adult",F2>=50,"Senior")} -> Adult | H2: Beauty | I2: 3 | J2: 50 | K2: =I2*J2 -> 150 | L2: =K2*$P$2 -> 2.25 | M2: =K2*$P$3 -> 3 | N2: {=_xlfn.IFS(C2=2023,K2*$P$2,C2=2024,K2*$P$3)} -> 2.25 | O2: Commission rate 2023 | P2: 0.015
A3: 2 | B3: 44984 | C3: =YEAR(B3) -> 2023 | D3: CUST002 | E3: Female | F3: 26 | G3: {=_xlfn.IFS(F3<30,"Young Adult",F3<50,"Adult",F3>=50,"Senior")} -> Young Adult | H3: Clothing | I3: 2 | J3: 500 | K3: =I3*J3 -> 1000 | L3: =K3*$P$2 -> 15 | M3: =K3*$P$3 -> 20 | N3: {=_xlfn.IFS(C3=2023,K3*$P$2,C3=2024,K3*$P$3)} -> 15 | O3: Commission rate 2024 | P3: 0.02
A4: 3 | B4: 44939 | C4: =YEAR(B4) -> 2023 | D4: CUST003 | E4: Male | F4: 50 | G4: {=_xlfn.IFS(F4<30,"Young Adult",F4<50,"Adult",F4>=50,"Senior")} -> Senior | H4: Electronics | I4: 1 | J4: 30 | K4: =I4*J4 -> 30 | L4: =K4*$P$2 -> 0.45 | M4: =K4*$P$3 -> 0.6 | N4: {=_xlfn.IFS(C4=2023,K4*$P$2,C4=2024,K4*$P$3)} -> 0.45
A5: 4 | B5: 45067 | C5: =YEAR(B5) -> 2023 | D5: CUST004 | E5: Male | F5: 37 | G5: {=_xlfn.IFS(F5<30,"Young Adult",F5<50,"Adult",F5>=50,"Senior")} -> Adult | H5: Clothing | I5: 1 | J5: 500 | K5: =I5*J5 -> 500 | L5: =K5*$P$2 -> 7.5 | M5: =K5*$P$3 -> 10 | N5: {=_xlfn.IFS(C5=2023,K5*$P$2,C5=2024,K5*$P$3)} -> 7.5
A6: 5 | B6: 45052 | C6: =YEAR(B6) -> 2023 | D6: CUST005 | E6: Male | F6: 30 | G6: {=_xlfn.IFS(F6<30,"Young Adult",F6<50,"Adult",F6>=50,"Senior")} -> Adult | H6: Beauty | I6: 2 | J6: 50 | K6: =I6*J6 -> 100 | L6: =K6*$P$2 -> 1.5 | M6: =K6*$P$3 -> 2 | N6: {=_xlfn.IFS(C6=2023,K6*$P$2,C6=2024,K6*$P$3)} -> 1.5
A7: 6 | B7: 45041 | C7: =YEAR(B7) -> 2023 | D7: CUST006 | E7: Female | F7: 45 | G7: {=_xlfn.IFS(F7<30,"Young Adult",F7<50,"Adult",F7>=50,"Senior")} -> Adult | H7: Beauty | I7: 1 | J7: 30 | K7: =I7*J7 -> 30 | L7: =K7*$P$2 -> 0.45 | M7: =K7*$P$3 -> 0.6 | N7: {=_xlfn.IFS(C7=2023,K7*$P$2,C7=2024,K7*$P$3)} -> 0.45
A8: 7 | B8: 44998 | C8: =YEAR(B8) -> 2023 | D8: CUST007 | E8: Male | F8: 46 | G8: {=_xlfn.IFS(F8<30,"Young Adult",F8<50,"Adult",F8>=50,"Senior")} -> Adult | H8: Clothing | I8: 2 | J8: 25 | K8: =I8*J8 -> 50 | L8: =K8*$P$2 -> 0.75 | M8: =K8*$P$3 -> 1 | N8: {=_xlfn.IFS(C8=2023,K8*$P$2,C8=2024,K8*$P$3)} -> 0.75
A9: 8 | B9: 44979 | C9: =YEAR(B9) -> 2023 | D9: CUST008 | E9: Male | F9: 30 | G9: {=_xlfn.IFS(F9<30,"Young Adult",F9<50,"Adult",F9>=50,"Senior")} -> Adult | H9: Electronics | I9: 4 | J9: 25 | K9: =I9*J9 -> 100 | L9: =K9*$P$2 -> 1.5 | M9: =K9*$P$3 -> 2 | N9: {=_xlfn.IFS(C9=2023,K9*$P$2,C9=2024,K9*$P$3)} -> 1.5
A10: 9 | B10: 45273 | C10: =YEAR(B10) -> 2023 | D10: CUST009 | E10: Male | F10: 63 | G10: {=_xlfn.IFS(F10<30,"Young Adult",F10<50,"Adult",F10>=50,"Senior")} -> Senior | H10: Electronics | I10: 2 | J10: 300 | K10: =I10*J10 -> 600 | L10: =K10*$P$2 -> 9 | M10: =K10*$P$3 -> 12 | N10: {=_xlfn.IFS(C10=2023,K10*$P$2,C10=2024,K10*$P$3)} -> 9 | O10: Total commission | P10: =SUM(N2:N1001) -> 6847.65
A11: 10 | B11: 45206 | C11: =YEAR(B11) -> 2023 | D11: CUST010 | E11: Female | F11: 52 | G11: {=_xlfn.IFS(F11<30,"Young Adult",F11<50,"Adult",F11>=50,"Senior")} -> Senior | H11: Clothing | I11: 4 | J11: 50 | K11: =I11*J11 -> 200 | L11: =K11*$P$2 -> 3 | M11: =K11*$P$3 -> 4 | N11: {=_xlfn.IFS(C11=2023,K11*$P$2,C11=2024,K11*$P$3)} -> 3 | O11: Average commission | P11: =AVERAGE(N2:N1001) -> 6.84765
A12: 11 | B12: 44971 | C12: =YEAR(B12) -> 2023 | D12: CUST011 | E12: Male | F12: 23 | G12: {=_xlfn.IFS(F12<30,"Young Adult",F12<50,"Adult",F12>=50,"Senior")} -> Young Adult | H12: Clothing | I12: 2 | J12: 50 | K12: =I12*J12 -> 100 | L12: =K12*$P$2 -> 1.5 | M12: =K12*$P$3 -> 2 | N12: {=_xlfn.IFS(C12=2023,K12*$P$2,C12=2024,K12*$P$3)} -> 1.5
A13: 12 | B13: 45229 | C13: =YEAR(B13) -> 2023 | D13: CUST012 | E13: Male | F13: 35 | G13: {=_xlfn.IFS(F13<30,"Young Adult",F13<50,"Adult",F13>=50,"Senior")} -> Adult | H13: Beauty | I13: 3 | J13: 25 | K13: =I13*J13 -> 75 | L13: =K13*$P$2 -> 1.125 | M13: =K13*$P$3 -> 1.5 | N13: {=_xlfn.IFS(C13=2023,K13*$P$2,C13=2024,K13*$P$3)} -> 1.125 | O13: Total commission | P13: =SUM(N2:N1001) -> 6847.65
A14: 13 | B14: 45143 | C14: =YEAR(B14) -> 2023 | D14: CUST013 | E14: Male | F14: 22 | G14: {=_xlfn.IFS(F14<30,"Young Adult",F14<50,"Adult",F14>=50,"Senior")} -> Young Adult | H14: Electronics | I14: 3 | J14: 500 | K14: =I14*J14 -> 1500 | L14: =K14*$P$2 -> 22.5 | M14: =K14*$P$3 -> 30 | N14: {=_xlfn.IFS(C14=2023,K14*$P$2,C14=2024,K14*$P$3)} -> 22.5 | O14: 2023 sales | P14: =SUMIF(C:C,2023,K:K) -> 454470
A15: 14 | B15: 44943 | C15: =YEAR(B15) -> 2023 | D15: CUST014 | E15: Male | F15: 64 | G15: {=_xlfn.IFS(F15<30,"Young Adult",F15<50,"Adult",F15>=50,"Senior")} -> Senior | H15: Clothing | I15: 4 | J15: 30 | K15: =I15*J15 -> 120 | L15: =K15*$P$2 -> 1.8 | M15: =K15*$P$3 -> 2.4 | N15: {=_xlfn.IFS(C15=2023,K15*$P$2,C15=2024,K15*$P$3)} -> 1.8 | O15: 2024 sales | P15: =SUMIF(C:C,2024,K:K) -> 1530
A16: 15 | B16: 44942 | C16: =YEAR(B16) -> 2023 | D16: CUST015 | E16: Female | F16: 42 | G16: {=_xlfn.IFS(F16<30,"Young Adult",F16<50,"Adult",F16>=50,"Senior")} -> Adult | H16: Electronics | I16: 4 | J16: 500 | K16: =I16*J16 -> 2000 | L16: =K16*$P$2 -> 30 | M16: =K16*$P$3 -> 40 | N16: {=_xlfn.IFS(C16=2023,K16*$P$2,C16=2024,K16*$P$3)} -> 30 | O16: 2023 AOV | P16: =AVERAGEIF(C:C,2023,K:K) -> 455.38076
A17: 16 | B17: 44974 | C17: =YEAR(B17) -> 2023 | D17: CUST016 | E17: Male | F17: 19 | G17: {=_xlfn.IFS(F17<30,"Young Adult",F17<50,"Adult",F17>=50,"Senior")} -> Young Adult | H17: Clothing | I17: 3 | J17: 500 | K17: =I17*J17 -> 1500 | L17: =K17*$P$2 -> 22.5 | M17: =K17*$P$3 -> 30 | N17: {=_xlfn.IFS(C17=2023,K17*$P$2,C17=2024,K17*$P$3)} -> 22.5 | O17: 2024 AOV | P17: =AVERAGEIF(C:C,2024,K:K) -> 765 | R17: =AVERAGEIFS(K:K,B:B,">="&DATE(2024,1,1),B:B,"<"&DATE(2025,1,1)) -> 765
A18: 17 | B18: 45038 | C18: =YEAR(B18) -> 2023 | D18: CUST017 | E18: Female | F18: 27 | G18: {=_xlfn.IFS(F18<30,"Young Adult",F18<50,"Adult",F18>=50,"Senior")} -> Young Adult | H18: Clothing | I18: 4 | J18: 25 | K18: =I18*J18 -> 100 | L18: =K18*$P$2 -> 1.5 | M18: =K18*$P$3 -> 2 | N18: {=_xlfn.IFS(C18=2023,K18*$P$2,C18=2024,K18*$P$3)} -> 1.5 | O18: 2023 commission | P18: =SUMIF(C:C,2023,N:N) -> 6817.05
A19: 18 | B19: 45046 | C19: =YEAR(B19) -> 2023 | D19: CUST018 | E19: Female | F19: 47 | G19: {=_xlfn.IFS(F19<30,"Young Adult",F19<50,"Adult",F19>=50,"Senior")} -> Adult | H19: Electronics | I19: 2 | J19: 25 | K19: =I19*J19 -> 50 | L19: =K19*$P$2 -> 0.75 | M19: =K19*$P$3 -> 1 | N19: {=_xlfn.IFS(C19=2023,K19*$P$2,C19=2024,K19*$P$3)} -> 0.75 | O19: 2024 commission | P19: =SUMIF(C:C,2024,N:N) -> 30.6
A20: 19 | B20: 45185 | C20: =YEAR(B20) -> 2023 | D20: CUST019 | E20: Female | F20: 62 | G20: {=_xlfn.IFS(F20<30,"Young Adult",F20<50,"Adult",F20>=50,"Senior")} -> Senior | H20: Clothing | I20: 2 | J20: 25 | K20: =I20*J20 -> 50 | L20: =K20*$P$2 -> 0.75 | M20: =K20*$P$3 -> 1 | N20: {=_xlfn.IFS(C20=2023,K20*$P$2,C20=2024,K20*$P$3)} -> 0.75
A21: 20 | B21: 45235 | C21: =YEAR(B21) -> 2023 | D21: CUST020 | E21: Male | F21: 22 | G21: {=_xlfn.IFS(F21<30,"Young Adult",F21<50,"Adult",F21>=50,"Senior")} -> Young Adult | H21: Clothing | I21: 3 | J21: 300 | K21: =I21*J21 -> 900 | L21: =K21*$P$2 -> 13.5 | M21: =K21*$P$3 -> 18 | N21: {=_xlfn.IFS(C21=2023,K21*$P$2,C21=2024,K21*$P$3)} -> 13.5
A22: 21 | B22: 44940 | C22: =YEAR(B22) -> 2023 | D22: CUST021 | E22: Female | F22: 50 | G22: {=_xlfn.IFS(F22<30,"Young Adult",F22<50,"Adult",F22>=50,"Senior")} -> Senior | H22: Beauty | I22: 1 | J22: 500 | K22: =I22*J22 -> 500 | L22: =K22*$P$2 -> 7.5 | M22: =K22*$P$3 -> 10 | N22: {=_xlfn.IFS(C22=2023,K22*$P$2,C22=2024,K22*$P$3)} -> 7.5
A23: 22 | B23: 45214 | C23: =YEAR(B23) -> 2023 | D23: CUST022 | E23: Male | F23: 18 | G23: {=_xlfn.IFS(F23<30,"Young Adult",F23<50,"Adult",F23>=50,"Senior")} -> Young Adult | H23: Clothing | I23: 2 | J23: 50 | K23: =I23*J23 -> 100 | L23: =K23*$P$2 -> 1.5 | M23: =K23*$P$3 -> 2 | N23: {=_xlfn.IFS(C23=2023,K23*$P$2,C23=2024,K23*$P$3)} -> 1.5 | O23: Total sales from women | P23: =SUMIF(E:E,"Female",K:K) -> 232840 | R23: AOV women | S23: =AVERAGEIF(E:E,"Female",K:K) -> 456.54902
A24: 23 | B24: 45028 | C24: =YEAR(B24) -> 2023 | D24: CUST023 | E24: Female | F24: 35 | G24: {=_xlfn.IFS(F24<30,"Young Adult",F24<50,"Adult",F24>=50,"Senior")} -> Adult | H24: Clothing | I24: 4 | J24: 30 | K24: =I24*J24 -> 120 | L24: =K24*$P$2 -> 1.8 | M24: =K24*$P$3 -> 2.4 | N24: {=_xlfn.IFS(C24=2023,K24*$P$2,C24=2024,K24*$P$3)} -> 1.8 | O24: Total sales from men | P24: =SUMIF(E:E,"Male",K:K) -> 223160 | R24: AOV men | S24: =AVERAGEIF(E:E,"Male",K:K) -> 455.42857
A25: 24 | B25: 45259 | C25: =YEAR(B25) -> 2023 | D25: CUST024 | E25: Female | F25: 49 | G25: {=_xlfn.IFS(F25<30,"Young Adult",F25<50,"Adult",F25>=50,"Senior")} -> Adult | H25: Clothing | I25: 1 | J25: 300 | K25: =I25*J25 -> 300 | L25: =K25*$P$2 -> 4.5 | M25: =K25*$P$3 -> 6 | N25: {=_xlfn.IFS(C25=2023,K25*$P$2,C25=2024,K25*$P$3)} -> 4.5
A26: 25 | B26: 45286 | C26: =YEAR(B26) -> 2023 | D26: CUST025 | E26: Female | F26: 64 | G26: {=_xlfn.IFS(F26<30,"Young Adult",F26<50,"Adult",F26>=50,"Senior")} -> Senior | H26: Beauty | I26: 1 | J26: 50 | K26: =I26*J26 -> 50 | L26: =K26*$P$2 -> 0.75 | M26: =K26*$P$3 -> 1 | N26: {=_xlfn.IFS(C26=2023,K26*$P$2,C26=2024,K26*$P$3)} -> 0.75
A27: 26 | B27: 45206 | C27: =YEAR(B27) -> 2023 | D27: CUST026 | E27: Female | F27: 28 | G27: {=_xlfn.IFS(F27<30,"Young Adult",F27<50,"Adult",F27>=50,"Senior")} -> Young Adult | H27: Electronics | I27: 2 | J27: 500 | K27: =I27*J27 -> 1000 | L27: =K27*$P$2 -> 15 | M27: =K27*$P$3 -> 20 | N27: {=_xlfn.IFS(C27=2023,K27*$P$2,C27=2024,K27*$P$3)} -> 15 | O27: Total sales under 30 | P27: =SUMIF(F:F,"<30",K:K) -> 123155 | R27: AOV under 30 | S27: =AVERAGEIF(F:F,"<30",K:K) -> 490.65737
A28: 27 | B28: 45141 | C28: =YEAR(B28) -> 2023 | D28: CUST027 | E28: Female | F28: 38 | G28: {=_xlfn.IFS(F28<30,"Young Adult",F28<50,"Adult",F28>=50,"Senior")} -> Adult | H28: Beauty | I28: 2 | J28: 25 | K28: =I28*J28 -> 50 | L28: =K28*$P$2 -> 0.75 | M28: =K28*$P$3 -> 1 | N28: {=_xlfn.IFS(C28=2023,K28*$P$2,C28=2024,K28*$P$3)} -> 0.75 | O28: Total sales 30-39 | P28: =SUMIFS(K:K,F:F,">=30",F:F,"<=39") -> 96325 | R28: AOV 30-39 | S28: =AVERAGEIFS(K:K,F:F,">=30",F:F,"<=39") -> 504.31937
A29: 28 | B29: 45039 | C29: =YEAR(B29) -> 2023 | D29: CUST028 | E29: Female | F29: 43 | G29: {=_xlfn.IFS(F29<30,"Young Adult",F29<50,"Adult",F29>=50,"Senior")} -> Adult | H29: Beauty | I29: 1 | J29: 500 | K29: =I29*J29 -> 500 | L29: =K29*$P$2 -> 7.5 | M29: =K29*$P$3 -> 10 | N29: {=_xlfn.IFS(C29=2023,K29*$P$2,C29=2024,K29*$P$3)} -> 7.5 | O29: Total sales 40+ | P29: =SUMIF(F:F,">=40",K:K) -> 236520 | R29: AOV 40+ | S29: =AVERAGEIF(F:F,">=40",K:K) -> 423.87097
A30: 29 | B30: 45156 | C30: =YEAR(B30) -> 2023 | D30: CUST029 | E30: Female | F30: 42 | G30: {=_xlfn.IFS(F30<30,"Young Adult",F30<50,"Adult",F30>=50,"Senior")} -> Adult | H30: Electronics | I30: 1 | J30: 30 | K30: =I30*J30 -> 30 | L30: =K30*$P$2 -> 0.45 | M30: =K30*$P$3 -> 0.6 | N30: {=_xlfn.IFS(C30=2023,K30*$P$2,C30=2024,K30*$P$3)} -> 0.45
A31: 30 | B31: 45228 | C31: =YEAR(B31) -> 2023 | D31: CUST030 | E31: Female | F31: 39 | G31: {=_xlfn.IFS(F31<30,"Young Adult",F31<50,"Adult",F31>=50,"Senior")} -> Adult | H31: Beauty | I31: 3 | J31: 300 | K31: =I31*J31 -> 900 | L31: =K31*$P$2 -> 13.5 | M31: =K31*$P$3 -> 18 | N31: {=_xlfn.IFS(C31=2023,K31*$P$2,C31=2024,K31*$P$3)} -> 13.5
A32: 31 | B32: 45069 | C32: =YEAR(B32) -> 2023 | D32: CUST031 | E32: Male | F32: 44 | G32: {=_xlfn.IFS(F32<30,"Young Adult",F32<50,"Adult",F32>=50,"Senior")} -> Adult | H32: Electronics | I32: 4 | J32: 300 | K32: =I32*J32 -> 1200 | L32: =K32*$P$2 -> 18 | M32: =K32*$P$3 -> 24 | N32: {=_xlfn.IFS(C32=2023,K32*$P$2,C32=2024,K32*$P$3)} -> 18 | O32: Beauty sales | P32: =SUMIF(H:H,"Beauty",K:K) -> 143515 | R32: Beauty AOV | S32: =AVERAGEIF(H:H,"Beauty",K:K) -> 467.47557
A33: 32 | B33: 44930 | C33: =YEAR(B33) -> 2023 | D33: CUST032 | E33: Male | F33: 30 | G33: {=_xlfn.IFS(F33<30,"Young Adult",F33<50,"Adult",F33>=50,"Senior")} -> Adult | H33: Beauty | I33: 3 | J33: 30 | K33: =I33*J33 -> 90 | L33: =K33*$P$2 -> 1.35 | M33: =K33*$P$3 -> 1.8 | N33: {=_xlfn.IFS(C33=2023,K33*$P$2,C33=2024,K33*$P$3)} -> 1.35 | O33: Clothing sales | P33: =SUMIF(H:H,"Clothing",K:K) -> 155580 | R33: Clothing AOV | S33: =AVERAGEIF(H:H,"Clothing",K:K) -> 443.24786
A34: 33 | B34: 45008 | C34: =YEAR(B34) -> 2023 | D34: CUST033 | E34: Female | F34: 50 | G34: {=_xlfn.IFS(F34<30,"Young Adult",F34<50,"Adult",F34>=50,"Senior")} -> Senior | H34: Electronics | I34: 2 | J34: 50 | K34: =I34*J34 -> 100 | L34: =K34*$P$2 -> 1.5 | M34: =K34*$P$3 -> 2 | N34: {=_xlfn.IFS(C34=2023,K34*$P$2,C34=2024,K34*$P$3)} -> 1.5 | O34: Electronics sales | P34: =SUMIF(H:H,"Electronics",K:K) -> 156905 | R34: Electronics AOV | S34: =AVERAGEIF(H:H,"Electronics",K:K) -> 458.78655
A35: 34 | B35: 45284 | C35: =YEAR(B35) -> 2023 | D35: CUST034 | E35: Female | F35: 51 | G35: {=_xlfn.IFS(F35<30,"Young Adult",F35<50,"Adult",F35>=50,"Senior")} -> Senior | H35: Clothing | I35: 3 | J35: 50 | K35: =I35*J35 -> 150 | L35: =K35*$P$2 -> 2.25 | M35: =K35*$P$3 -> 3 | N35: {=_xlfn.IFS(C35=2023,K35*$P$2,C35=2024,K35*$P$3)} -> 2.25
A36: 35 | B36: 45143 | C36: =YEAR(B36) -> 2023 | D36: CUST035 | E36: Female | F36: 58 | G36: {=_xlfn.IFS(F36<30,"Young Adult",F36<50,"Adult",F36>=50,"Senior")} -> Senior | H36: Beauty | I36: 3 | J36: 300 | K36: =I36*J36 -> 900 | L36: =K36*$P$2 -> 13.5 | M36: =K36*$P$3 -> 18 | N36: {=_xlfn.IFS(C36=2023,K36*$P$2,C36=2024,K36*$P$3)} -> 13.5 | O36: WOMEN | R36: MEN
A37: 36 | B37: 45101 | C37: =YEAR(B37) -> 2023 | D37: CUST036 | E37: Male | F37: 52 | G37: {=_xlfn.IFS(F37<30,"Young Adult",F37<50,"Adult",F37>=50,"Senior")} -> Senior | H37: Beauty | I37: 3 | J37: 300 | K37: =I37*J37 -> 900 | L37: =K37*$P$2 -> 13.5 | M37: =K37*$P$3 -> 18 | N37: {=_xlfn.IFS(C37=2023,K37*$P$2,C37=2024,K37*$P$3)} -> 13.5 | O37: Beauty sales | P37: =SUMIFS(K:K,E:E,"Female",H:H,"Beauty") -> 74830 | R37: Beauty sales | S37: =SUMIFS(K:K,E:E,"Male",H:H,"Beauty") -> 68685
A38: 37 | B38: 45069 | C38: =YEAR(B38) -> 2023 | D38: CUST037 | E38: Female | F38: 18 | G38: {=_xlfn.IFS(F38<30,"Young Adult",F38<50,"Adult",F38>=50,"Senior")} -> Young Adult | H38: Beauty | I38: 3 | J38: 25 | K38: =I38*J38 -> 75 | L38: =K38*$P$2 -> 1.125 | M38: =K38*$P$3 -> 1.5 | N38: {=_xlfn.IFS(C38=2023,K38*$P$2,C38=2024,K38*$P$3)} -> 1.125 | O38: Clothing sales | P38: =SUMIFS(K:K,E:E,"Female",H:H,"Clothing") -> 81275 | R38: Clothing sales | S38: =SUMIFS(K:K,E:E,"Male",H:H,"Clothing") -> 74305
A39: 38 | B39: 45006 | C39: =YEAR(B39) -> 2023 | D39: CUST038 | E39: Male | F39: 38 | G39: {=_xlfn.IFS(F39<30,"Young Adult",F39<50,"Adult",F39>=50,"Senior")} -> Adult | H39: Beauty | I39: 4 | J39: 50 | K39: =I39*J39 -> 200 | L39: =K39*$P$2 -> 3 | M39: =K39*$P$3 -> 4 | N39: {=_xlfn.IFS(C39=2023,K39*$P$2,C39=2024,K39*$P$3)} -> 3 | O39: Electronics sales | P39: =SUMIFS(K:K,E:E,"Female",H:H,"Electronics") -> 76735 | R39: Electronics sales | S39: =SUMIFS(K:K,E:E,"Male",H:H,"Electronics") -> 80170
A40: 39 | B40: 45037 | C40: =YEAR(B40) -> 2023 | D40: CUST039 | E40: Male | F40: 23 | G40: {=_xlfn.IFS(F40<30,"Young Adult",F40<50,"Adult",F40>=50,"Senior")} -> Young Adult | H40: Clothing | I40: 4 | J40: 30 | K40: =I40*J40 -> 120 | L40: =K40*$P$2 -> 1.8 | M40: =K40*$P$3 -> 2.4 | N40: {=_xlfn.IFS(C40=2023,K40*$P$2,C40=2024,K40*$P$3)} -> 1.8
...

Sheet Transactions
A1: Transaction ID | B1: Total Sales | C1: Product category | D1: Concatenate
A2: 10 | B2: =VLOOKUP(A2,'retail_sales_dataset (2)'!A:K,11,FALSE) -> 200 | C2: =VLOOKUP(A2,'retail_sales_dataset (2)'!A:K,8,FALSE) -> Clothing | D2: =_xlfn.CONCAT(B2," ",C2) -> 200 Clothing
A3: 15 | B3: =VLOOKUP(A3,'retail_sales_dataset (2)'!A:K,11,FALSE) -> 2000 | C3: =VLOOKUP(A3,'retail_sales_dataset (2)'!A:K,8,FALSE) -> Electronics | D3: =_xlfn.CONCAT(B3," ",C3) -> 2000 Electronics
A4: 25 | B4: =VLOOKUP(A4,'retail_sales_dataset (2)'!A:K,11,FALSE) -> 50 | C4: =VLOOKUP(A4,'retail_sales_dataset (2)'!A:K,8,FALSE) -> Beauty | D4: =_xlfn.CONCAT(B4," ",C4) -> 50 Beauty
A5: 30 | B5: =VLOOKUP(A5,'retail_sales_dataset (2)'!A:K,11,FALSE) -> 900 | C5: =VLOOKUP(A5,'retail_sales_dataset (2)'!A:K,8,FALSE) -> Beauty | D5: =_xlfn.CONCAT(B5," ",C5) -> 900 Beauty
A6: 54 | B6: =VLOOKUP(A6,'retail_sales_dataset (2)'!A:K,11,FALSE) -> 1500 | C6: =VLOOKUP(A6,'retail_sales_dataset (2)'!A:K,8,FALSE) -> Electronics | D6: =_xlfn.CONCAT(B6," ",C6) -> 1500 Electronics
A7: 55 | B7: =VLOOKUP(A7,'retail_sales_dataset (2)'!A:K,11,FALSE) -> 120 | C7: =VLOOKUP(A7,'retail_sales_dataset (2)'!A:K,8,FALSE) -> Beauty | D7: =_xlfn.CONCAT(B7," ",C7) -> 120 Beauty
A8: 67 | B8: =VLOOKUP(A8,'retail_sales_dataset (2)'!A:K,11,FALSE) -> 1200 | C8: =VLOOKUP(A8,'retail_sales_dataset (2)'!A:K,8,FALSE) -> Beauty | D8: =_xlfn.CONCAT(B8," ",C8) -> 1200 Beauty
A9: 89 | B9: =VLOOKUP(A9,'retail_sales_dataset (2)'!A:K,11,FALSE) -> 2000 | C9: =VLOOKUP(A9,'retail_sales_dataset (2)'!A:K,8,FALSE) -> Electronics | D9: =_xlfn.CONCAT(B9," ",C9) -> 2000 Electronics
A10: 100 | B10: =VLOOKUP(A10,'retail_sales_dataset (2)'!A:K,11,FALSE) -> 30 | C10: =VLOOKUP(A10,'retail_sales_dataset (2)'!A:K,8,FALSE) -> Electronics | D10: =_xlfn.CONCAT(B10," ",C10) -> 30 Electronics
A12: =COUNT(A2:A10) -> 9 | B12: =COUNT(B2:B10) -> 9 | C12: =COUNT(C2:C10) -> 0 | D12: =COUNT(D2:D10) -> 0
A14: =COUNTA(A2:A10) -> 9 | B14: =COUNTA(B2:B10) -> 9 | C14: =COUNTA(C2:C10) -> 9 | D14: =COUNTA(D2:D10) -> 9
